Workbook

Sheet Summary
B1: Total | C1: =SUM(C3:C62) -> 417
B2: Group | C2: Count | E2: Cost | F2: Count
B3: {=_xlfn.UNIQUE(_xlfn._xlws.FILTER(Combined!G2:G1000,Combined!G2:G1000<>"",Combined!G2:G1000<>""))} -> Spiritual | C3: =COUNTIF(Combined!$G$2:$G$1065, Summary!B3) -> 28 | E3: {=_xlfn._xlws.SORT(_xlfn.UNIQUE(_xlfn._xlws.FILTER(Combined!D2:D1000,Combined!D2:D1000<>"",Combined!D2:D1000<>"")))} -> 0 | F3: =COUNTIF(Combined!$D$2:$D$1065, Summary!E3) -> 8
B4: Psychic | C4: =COUNTIF(Combined!$G$2:$G$1065, Summary!B4) -> 25 | E4: 25 | F4: =COUNTIF(Combined!$D$2:$D$1065, Summary!E4) -> 8
B5: Martial | C5: =COUNTIF(Combined!$G$2:$G$1065, Summary!B5) -> 27 | E5: 50 | F5: =COUNTIF(Combined!$D$2:$D$1065, Summary!E5) -> 2
B6: Alchemy | C6: =COUNTIF(Combined!$G$2:$G$1065, Summary!B6) -> 29 | E6: 100 | F6: =COUNTIF(Combined!$D$2:$D$1065, Summary!E6) -> 37
B7: Magic | C7: =COUNTIF(Combined!$G$2:$G$1065, Summary!B7) -> 28 | E7: 150 | F7: =COUNTIF(Combined!$D$2:$D$1065, Summary!E7) -> 32
B8: Eldritch | C8: =COUNTIF(Combined!$G$2:$G$1065, Summary!B8) -> 26 | E8: 175 | F8: =COUNTIF(Combined!$D$2:$D$1065, Summary!E8) -> 1
B9: Planar | C9: =COUNTIF(Combined!$G$2:$G$1065, Summary!B9) -> 24 | E9: 200 | F9: =COUNTIF(Combined!$D$2:$D$1065, Summary!E9) -> 112
B10: Physics | C10: =COUNTIF(Combined!$G$2:$G$1065, Summary!B10) -> 41 | E10: 250 | F10: =COUNTIF(Combined!$D$2:$D$1065, Summary!E10) -> 24
B11: General | C11: =COUNTIF(Combined!$G$2:$G$1065, Summary!B11) -> 98 | E11: 300 | F11: =COUNTIF(Combined!$D$2:$D$1065, Summary!E11) -> 63
B12: Stuff | C12: =COUNTIF(Combined!$G$2:$G$1065, Summary!B12) -> 58 | E12: 350 | F12: =COUNTIF(Combined!$D$2:$D$1065, Summary!E12) -> 13
B13: Powers | C13: =COUNTIF(Combined!$G$2:$G$1065, Summary!B13) -> 33 | E13: 400 | F13: =COUNTIF(Combined!$D$2:$D$1065, Summary!E13) -> 18
C14: =COUNTIF(Combined!$G$2:$G$1065, Summary!B14) -> 0 | E14: 450 | F14: =COUNTIF(Combined!$D$2:$D$1065, Summary!E14) -> 2
C15: =COUNTIF(Combined!$G$2:$G$1065, Summary!B15) -> 0 | E15: 500 | F15: =COUNTIF(Combined!$D$2:$D$1065, Summary!E15) -> 48
C16: =COUNTIF(Combined!$G$2:$G$1065, Summary!B16) -> 0 | E16: 550 | F16: =COUNTIF(Combined!$D$2:$D$1065, Summary!E16) -> 1
C17: =COUNTIF(Combined!$G$2:$G$1065, Summary!B17) -> 0 | E17: 600 | F17: =COUNTIF(Combined!$D$2:$D$1065, Summary!E17) -> 8
C18: =COUNTIF(Combined!$G$2:$G$1065, Summary!B18) -> 0 | E18: 750 | F18: =COUNTIF(Combined!$D$2:$D$1065, Summary!E18) -> 15
C19: =COUNTIF(Combined!$G$2:$G$1065, Summary!B19) -> 0 | E19: 800 | F19: =COUNTIF(Combined!$D$2:$D$1065, Summary!E19) -> 1
C20: =COUNTIF(Combined!$G$2:$G$1065, Summary!B20) -> 0 | E20: 900 | F20: =COUNTIF(Combined!$D$2:$D$1065, Summary!E20) -> 2
C21: =COUNTIF(Combined!$G$2:$G$1065, Summary!B21) -> 0 | E21: 1000 | F21: =COUNTIF(Combined!$D$2:$D$1065, Summary!E21) -> 16
C22: =COUNTIF(Combined!$G$2:$G$1065, Summary!B22) -> 0 | E22: 1200 | F22: =COUNTIF(Combined!$D$2:$D$1065, Summary!E22) -> 6
C23: =COUNTIF(Combined!$G$2:$G$1065, Summary!B23) -> 0
C24: =COUNTIF(Combined!$G$2:$G$1065, Summary!B24) -> 0
C25: =COUNTIF(Combined!$G$2:$G$1065, Summary!B25) -> 0
C26: =COUNTIF(Combined!$G$2:$G$1065, Summary!B26) -> 0
C27: =COUNTIF(Combined!$G$2:$G$1065, Summary!B27) -> 0
C28: =COUNTIF(Combined!$G$2:$G$1065, Summary!B28) -> 0
C29: =COUNTIF(Combined!$G$2:$G$1065, Summary!B29) -> 0
C30: =COUNTIF(Combined!$G$2:$G$1065, Summary!B30) -> 0
C31: =COUNTIF(Combined!$G$2:$G$1065, Summary!B31) -> 0
C32: =COUNTIF(Combined!$G$2:$G$1065, Summary!B32) -> 0
C33: =COUNTIF(Combined!$G$2:$G$1065, Summary!B33) -> 0
C34: =COUNTIF(Combined!$G$2:$G$1065, Summary!B34) -> 0
... C60: =COUNTIF(Combined!$G$2:$G$1065, Summary!B60) -> 0

Sheet Combined
A1: ID | B1: Name | C1: Description | D1: Cost | E1: Repeatable | F1: Dependency | G1: Group
A2: 0 | B2: Spiritual Energy | C2: The stuff that makes up souls. that undefinable thing that still defines everything. Everything makes it all the time, though you perhaps make more than usual. You are now able to manipulate it to your own ends | D2: 0 | E2: max | F2: 0 | G2: Spiritual
A3: 1 | B3: The Root of Meaning | C3: There is meaning to this world. Yet, if you ground all of existence into it's finest components and searched through it all, you would find none. It is this paradox that you now command, to be able to empower the very meaning that is born of form | D3: 300 | E3: 1 | F3: Spiritual Energy | G3: Spiritual
A4: 2 | B4: Divine Insight | C4: Gods Exist. Or do they? Born of belief yet having always existed, it is difficult to say if people created gods or gods created people. The answer to that dichotomy is the core to divinity - the end result of Meaning enforced upon existence through collective action. And that is a secret you now hold in your heart of hearts | D4: 300 | E4: 1 | F4: Spiritual Energy | G4: Spiritual
A5: 3 | B5: Sword Intent | C5: Or anything intent, really, you know how to imbue spiritual energy into items you craft giving them the beginnings of sentience. Though they will never develop any true sapience, they are born with 'instincts' regarding their proper use and will learn alongside their wielders. They can make their desires known to their operators and function better than they physically should, growing as their souls do. | D5: 300 | E5: 1 | F5: Spiritual Energy | G5: Spiritual
A6: 4 | B6: Spirits | C6: Not quite souls, but perhaps something along the way. Spiritual constructs with a degree of agency capable of carrying out specific tasks and acting in a specific manner are far simpler to make and can | D6: 600 | E6: 1 | F6: Spiritual Energy | G6: Spiritual
A7: 5 | B7: Souls | C7: Souls are a complex thing. Yet, ultimately, quite simple to make. Even the complex souls of people are often created though complete accident. Indeed, a simple object well cared for will eventually gain an identity strong enough to form a soul. You now understand this principle that with sufficient study you can create souls of varying complexity from simple rocks to the intricate existences of people and possibly beyond. | D7: 900 | E7: 1 | F7: Spiritual Energy | G7: Spiritual
A8: 6 | B8: Elementals | C8: Elementals are interesting things. In many ways, they are concepts, enforced onto the world souls that have no need for a form to interact with the world. Though, perhaps because of this, they tend to be... otherwise simple. Still, you understand how to reinforce spiritual structures so that they may influence the wider world without a supporting anchor. | D8: 600 | E8: 1 | F8: Spiritual Energy | G8: Spiritual
A9: 7 | B9: Ichor | C9: Said to be the blood of gods, this material is effectively condensed spiritual energy, rendered into a mores table form. This has a number of uses, though that might require some experimentation for you to uncover | D9: 300 | E9: 1 | F9: Spiritual Energy | G9: Spiritual
A10: 8 | B10: Altar | C10: These devices gather devotion, the deliberate act of sacrifice in order to venerate another, be that of time or something more material. When these acts are performed at an alter, it empowers the souls of the item in question. | D10: 300 | E10: 1 | F10: Divine Insight | G10: Spiritual
A11: 9 | B11: Icon | C11: These devices gather faith, the deep seated belief in the capabilities of something. This empowers that soul to act within the vicinity of the icon, dependent on the belief of the wielder. | D11: 300 | E11: 1 | F11: Divine Insight | G11: Spiritual
A12: 10 | B12: Offering | C12: By preparing an object and ritually destroying it, you can grant strength to the items that you wish to empower. This imbues them with additional spiritual strength, which can be improved by preparing specific offering in line with the soul in question. This also improves the quality of the object to a supernatural degree. | D12: 300 | E12: 1 | F12: Divine Insight | G12: Spiritual
A13: 11 | B13: Pact | C13: A sufficiently powerful soul may grant a portion of it's power to another, bestowing them with a measure of their strength. In doing so however, the recipient is bound to the terms of the transfer. | D13: 600 | E13: 1 | F13: Spiritual Energy | G13: Spiritual
A14: 12 | B14: Demesne | C14: An space claimed by a sufficiently powerful soul can, with time, be suffused with their strength, empowering allies and weakening foes. The strength of this depends of the age of the claim and the power of the soul in question | D14: 300 | E14: 1 | F14: Spiritual Energy | G14: Spiritual
... A23: 21 | B23: Unhallowed Ground | C23: You can prepare a space such that it is inimitable to spiritual presences, and are capable of optimising the effect for specific groups or individual examples for greater effect given sufficient knowledge of them. At a base level, this offers resistance to their influence but can scale to utterly barring them from being able to access the space. | D23: 500 | E23: 1 | F23: Spiritual Energy | G23: Spiritual
A24: 22 | B24: Psionics | C24: The true power of Mind over Matter. Though it is not limited to the realm of the material psionic energy is a manifestation of your inner self on the outside world. This grants basic psionic abilities, though nothing exceptional | D24: 0 | E24: MAX | F24: 0 | G24: Psychic
A25: 23 | B25: WE/YOU/I ARE ONE | C25: Your mind is a part of a greater whole thoughts and beliefs flow in and out. The boundary of your existence if far more permeable than you would have thought and you know how to have your mind reach out, feel and manipulate | D25: 300 | E25: 1 | F25: Psionics | G25: Psychic
A26: 24 | B26: Where Do I End | C26: You are a part of the universe. A part that thinks. But where do you end? You have a command over your existence that most of it does not have, and with the right Will, you may enforce that command over more than thoughts | D26: 300 | E26: 1 | F26: Psionics | G26: Psychic
A27: 25 | B27: Technokinesis | C27: What is technology, but the dreams of people made manifest. Technology has a particular relationship with psionic energies, and you now have the aptitude necessary to directly interface with technology of all kinds with your psychic prowess. | D27: 500 | E27: 1 | F27: Psionics | G27: Psychic
A28: 26 | B28: Thermokinesis | C28: Though some might think of this as pyrokinesis, in truth, this is a broader discipline. Temperature is a fundamental part of reality, and one that you can now exercise some serious control over. | D28: 300 | E28: 1 | F28: Psionics | G28: Psychic
A29: 27 | B29: Photokinesis | C29: Though it may seem as though telekinesis creates energy, that is largely a side effect of the resultant movement. Truly creating energy from psionic power is actually fairly tricky. Still, you now have the aptitude and basic skills necessary to generate bursts of light and even manipulate existing photons through psionic might. | D29: 300 | E29: 1 | F29: Psionics | G29: Psychic
A30: 28 | B30: Electrokinesis | C30: Manipulating something as small and uncertain as electrons requires a delicate touch and a certain mentality that you now possess. Not only are you able to make electrons dance, but you can also generate magnetic fields through will alone. | D30: 300 | E30: 1 | F30: Psionics | G30: Psychic
A31: 29 | B31: Psionic Integration | C31: Psychoactive materials are quite difficult to make, but an integral part of any psionic technology that doesn't involve an ability for self-determination. You gain the fundamental knowledge necessary needed to build psionic devices, including the relevant structural and chemical theory | D31: 300 | E31: 1 | F31: Psionics | G31: Psychic
A32: 30 | B32: Telepathic Interface | C32: Controlling devices with your mind is an interesting prospect, though one that generally requires another mind to link with. With careful application however, you can create a system that operates almost as an extension of the user, receiving and sending telepathic signals that can allow for the use of complex systems | D32: 300 | E32: 1 | F32: Psionic Integration | G32: Psychic
A33: 31 | B33: Telekinetic Arrays | C33: Ah, motive force. The fundamental interface between the now and will be. Producing this through artificial means is the core of creating psionic technology with an ability to impact the physical world. | D33: 300 | E33: 1 | F33: Psionic Integration | G33: Psychic
A34: 32 | B34: Illusionary Systems | C34: Illusions are an interesting aspect of the psionic arts. Though some believe it could be considered an aspect of telepathy, the truth is that illusions are far more complex constructs, capable of programmed action independent of direct control. These psionic constructs can effectively be used as incredibly versatile components that can be altered as necessary | D34: 300 | E34: 1 | F34: Psionic Integration | G34: Psychic
A35: 33 | B35: Mimetic Technology | C35: Ideas are the genetics of civilisation, from opinions to traditions, being able to create mental constructs that spread and persist is both easy and incredibly difficult. Simple earworms are but party tricks compared to what you are capable of. | D35: 500 | E35: 1 | F35: Psionics | G35: Psychic
A36: 34 | B36: Empathic Sensors | C36: Reaching into the subconscious is quite tricky, but necessary for a wide variety of purposes. Through various complex psionic processes, you can create sensors that pick up emotion, desires, intent and all the other underlying currents of the mind | D36: 300 | E36: 1 | F36: Psionic Integration | G36: Psychic
... A43: 41 | B43: Mental Helm | C43: This physical object, when placed in proximity to the seat of consciousness imbues it's wearer with powerful psionic protections, allowing them to shrug off almost any mental intrusion. | D43: 200 | E43: 1 | F43: Psionic Integration | G43: Psychic
A44: 42 | B44: Ki | C44: A mystical energy associated with feats of physical and athletic prowess. This energy grows in response to physical exertion and tends produce results for physical training beyond what would be considered natural. This grants you capabilities equal to an average adept, nothing particularly special, but nothing to be concerned about either | D44: 0 | E44: MAX | F44: 0 | G44: Martial
A45: 43 | B45: Put Your Back Into It | C45: Ki is substance, it is existence. You know how to call upon this energy and put your whole self into everything you do. In addition to magnifying the effects of your actions, it allows you a control over the outcome of your actions beyond what is physically possible. | D45: 300 | E45: 1 | F45: Ki | G45: Martial
A46: 44 | B46: Martial Reinforcement | C46: You know how to flow your Ki into objects you wield making them more durable and effective. You skill in this grows with time and power, but even initially, you can empower swords enough to cut through wooden posts without so much as dulling the blade. | D46: 300 | E46: 1 | F46: Ki | G46: Martial
A47: 45 | B47: Legendary Smith | C47: Your works are just better. Better than they have any right to me. Perhaps it is the ki adding more than strength to your blows, producing works that are orders of magnitude more capable than they really should be. | D47: 300 | E47: 1 | F47: Ki | G47: Martial
A48: 46 | B48: Beat it into Them | C48: Demonstrating, but the real way to learn how to fight is to fight. You can train people incredibly quickly through a combination of demonstration and sparring forcing proper form and technique into the minds of your students | D48: 300 | E48: 1 | F48: Ki | G48: Martial
A49: 47 | B49: Attuned Tools | C49: It normally takes years to get used to a tool, to know it as you know yourself. However, with sufficient skill a craftsman can create a tool designed for a single person, allowing them to wield it with such ease that it is better than anything else comparable would be in their hands and take to Ki augmentation particularly well | D49: 300 | E49: 1 | F49: Ki | G49: Martial
A50: 48 | B50: Prized Bloodline | C50: Certain fighters have specific talents, born of pure chance or breeding programs that might have gone on for generations. Not only can you identify the martial talents put in front of you, you can also isolate and replicate these factors in others | D50: 300 | E50: 1 | F50: Ki | G50: Martial
A51: 49 | B51: Strict Diet | C51: You are what you eat. Not only do you know what food is best for what purposes, but based on the resources you have available to you, you also know how to create the optimal possible diet for any given outcome, significantly accelerating progress. This also works for abnormal nutrition requirements like specific kinds of blood for vampires or alternative fuel sources for androids | D51: 300 | E51: 1 | F51: Ki | G51: Martial
A52: 50 | B52: Technique Scrolls | C52: Getting the intricacies of martial technique to survive you is tricky. Martial arts is not often best described by words and pictures. But you can do it. In fact, you know exactly how to produce instructional materials of all kinds that are incredibly instructive items capable of perfectly pouring knowledge into even the poorest of pupils | D52: 300 | E52: 1 | F52: 0 | G52: Martial
A53: 51 | B53: Strange Concoctions | C53: These substances work far better than they should. Taking advantage of the supernatural qualities of Ki, these substances are able to perform feats that could be considered miraculous. They can cure mortal wounds, grant immense stamina or incredible strength or speed | D53: 400 | E53: 1 | F53: Ki | G53: Martial
A54: 52 | B54: Extreme Training | C54: Ki makes things that might seem impractical entirely possible. Be it carrying around massive rocks, or dodging arrows blindfolded, you know how to get extreme results from extreme effort, the more extreme the better | D54: 500 | E54: 1 | F54: Ki | G54: Martial
...
